<?xml version="1.0" ?>
<sdf version="1.8">
  <model name="diff_drive_robot">
    <pose>0 0 0.1 0 0 0</pose>
    
    <link name="base_link">
      <inertial>
        <mass>5.0</mass>
        <inertia>
          <ixx>0.05</ixx><iyy>0.05</iyy><izz>0.08</izz>
        </inertia>
      </inertial>
      <collision name="collision">
        <geometry><box><size>0.5 0.4 0.1</size></box></geometry>
      </collision>
      <visual name="visual">
        <geometry><box><size>0.5 0.4 0.1</size></box></geometry>
        <material><ambient>0.2 0.2 0.8 1</ambient><diffuse>0.2 0.2 0.8 1</diffuse></material>
      </visual>
    </link>

    <link name="left_wheel">
      <pose>0.15 0.225 -0.025 -1.5707 0 0</pose>
      <collision name="collision">
        <geometry><cylinder><radius>0.1</radius><length>0.05</length></cylinder></geometry>
      </collision>
      <visual name="visual">
        <geometry><cylinder><radius>0.1</radius><length>0.05</length></cylinder></geometry>
        <material><ambient>0.1 0.1 0.1 1</ambient><diffuse>0.1 0.1 0.1 1</diffuse></material>
      </visual>
    </link>

    <link name="right_wheel">
      <pose>0.15 -0.225 -0.025 -1.5707 0 0</pose>
      <collision name="collision">
        <geometry><cylinder><radius>0.1</radius><length>0.05</length></cylinder></geometry>
      </collision>
      <visual name="visual">
        <geometry><cylinder><radius>0.1</radius><length>0.05</length></cylinder></geometry>
        <material><ambient>0.1 0.1 0.1 1</ambient><diffuse>0.1 0.1 0.1 1</diffuse></material>
      </visual>
    </link>

    <link name="caster">
      <pose>-0.2 0 -0.08 0 0 0</pose>
      <collision name="collision">
        <geometry><sphere><radius>0.05</radius></sphere></geometry>
      </collision>
      <visual name="visual">
        <geometry><sphere><radius>0.05</radius></sphere></geometry>
        <material><ambient>0.1 0.1 0.1 1</ambient><diffuse>0.1 0.1 0.1 1</diffuse></material>
      </visual>
    </link>

    <link name="lidar_link">
      <pose>0.2 0 0.1 0 0 0</pose>
      <inertial>
        <mass>0.1</mass>
        <inertia><ixx>0.001</ixx><iyy>0.001</iyy><izz>0.001</izz></inertia>
      </inertial>
      <visual name="visual">
        <geometry><cylinder><radius>0.04</radius><length>0.05</length></cylinder></geometry>
        <material><ambient>0.8 0.1 0.1 1</ambient><diffuse>0.8 0.1 0.1 1</diffuse></material>
      </visual>
      <sensor name="gpu_lidar" type="gpu_lidar">
        <always_on>1</always_on>
        <visualize>true</visualize> <update_rate>10</update_rate>
        <lidar>
          <scan>
            <horizontal>
              <samples>640</samples><resolution>1</resolution><min_angle>-3.14159</min_angle><max_angle>3.14159</max_angle>
            </horizontal>
          </scan>
          <range><min>0.15</min><max>12.0</max></range>
        </lidar>
      </sensor>
    </link>

    <joint name="left_wheel_joint" type="revolute">
      <parent>base_link</parent>
      <child>left_wheel</child>
      <axis>
        <xyz>0 0 1</xyz>
        <limit>
          <lower>-1.79769e+308</lower>
          <upper>1.79769e+308</upper>
        </limit>
      </axis>
    </joint>

    <joint name="right_wheel_joint" type="revolute">
      <parent>base_link</parent>
      <child>right_wheel</child>
      <axis>
        <xyz>0 0 1</xyz>
        <limit>
          <lower>-1.79769e+308</lower>
          <upper>1.79769e+308</upper>
        </limit>
      </axis>
    </joint>

    <joint name="caster_joint" type="ball">
      <parent>base_link</parent>
      <child>caster</child>
    </joint>

    <joint name="lidar_joint" type="fixed">
      <parent>base_link</parent>
      <child>lidar_link</child>
    </joint>

    <plugin filename="gz-sim-diff-drive-system" name="gz::sim::systems::DiffDrive">
        <left_joint>left_wheel_joint</left_joint>
        <right_joint>right_wheel_joint</right_joint>
        <wheel_separation>0.45</wheel_separation>
        <wheel_radius>0.1</wheel_radius>
        </plugin>

    <plugin filename="gz-sim-pose-publisher-system" name="gz::sim::systems::PosePublisher">
        <publish_link_pose>true</publish_link_pose>
        <use_pose_vector_msg>true</use_pose_vector_msg>
        <publish_nested_model_pose>true</publish_nested_model_pose>
    </plugin>
  </model>
</sdf>
